Workbook
Name _____a1: #REF!
Name _____a1: #REF!
Name _____a1: #REF!
Name _____a1: #REF!
Name _____a1: #REF!
Name ____a1: #REF!
Name ____a1: #REF!
Name ____a1: #REF!
Name ____a1: #REF!
Name ____a1: #REF!
Name ___a1: #REF!
Name ___a1: #REF!
Name ___a1: #REF!
Name ___a1: #REF!
Name ___a1: #REF!
Name __a1: #REF!
Name __a1: #REF!
Name __a1: #REF!
Name __a1: #REF!
Name __a1: #REF!
Name _a1: #REF!
Name _a1: #REF!
Name _a1: #REF!
Name _a1: #REF!
Name _a1: #REF!
Name _Toc116380018: 'D&R'!#REF!
Name _Toc116380018: 'Environment Mgmt'!#REF!
Name _Toc116380018: HMI!#REF!
Name _Toc116380018: 'P & D'!#REF!
Name _Toc116380018: Safety!#REF!
Name _Toc116380018: 'Thermal Aerodynamics System Eng'!#REF!
Name _Toc116380018: 'Utility & Usage'!#REF!
Name _Toc260205582: 'D&R'!#REF!
Name _Toc260205582: 'Environment Mgmt'!#REF!
Name _Toc260205582: HMI!#REF!
Name _Toc260205582: 'P & D'!#REF!
Name _Toc260205582: Safety!#REF!
Name _Toc260205582: 'Thermal Aerodynamics System Eng'!#REF!
Name _Toc260205582: 'Utility & Usage'!#REF!
Name _Toc308099769: 'D&R'!#REF!
Name _Toc308099769: 'Environment Mgmt'!#REF!
Name _Toc308099769: HMI!#REF!
Name _Toc308099769: 'P & D'!#REF!
Name _Toc308099769: Safety!#REF!
Name _Toc308099769: 'Thermal Aerodynamics System Eng'!#REF!
Name _Toc308099769: 'Utility & Usage'!#REF!
Name _Toc6661815: 'D&R'!#REF!
Name _Toc6661815: 'Environment Mgmt'!#REF!
Name _Toc6661815: HMI!#REF!
Name _Toc6661815: 'P & D'!#REF!
Name _Toc6661815: Safety!#REF!
Name _Toc6661815: 'Thermal Aerodynamics System Eng'!#REF!
Name _Toc6661815: 'Utility & Usage'!#REF!
Name _Toc6661871: 'D&R'!#REF!
Name _Toc6661871: 'Environment Mgmt'!#REF!
Name _Toc6661871: HMI!#REF!
Name _Toc6661871: 'P & D'!#REF!
Name _Toc6661871: Safety!#REF!
Name _Toc6661871: 'Thermal Aerodynamics System Eng'!#REF!
Name _Toc6661871: 'Utility & Usage'!#REF!

Sheet Veh PALs

Sheet Panel chart summary
G1: LEGEND : no.of RED/YELLOW/GREEN/Not assessable | K1: Data for graphs (Not to be presented )
B2: X-in-1 : Panel Chart Summary | K2: Data for Graphs-Current status | Q2: Data for Graphs-Projected Status at SOP
B3: # | C3: Attribute | D3: PALS | G3: Total targets | H3: Current Status at AKO | I3: Projected Status at ESO | K3: Status of Assessed targets | N3: Not Assessable | O3: Assessable | Q3: Status of Assessed targets | T3: Not Assessable | U3: Assessable
D4: Target | E4: Current status | F4: SOP Status (F) | K4: Red | L4: Yellow | M4: Green | Q4: Red | R4: Yellow | S4: Green
B5: A1 | C5: Performance & Drivability | D5: AL | E5: - | F5: - | G5: =SUM(K5+L5+M5+N5) -> 69 | K5: ='P & D'!M2 -> 0 | L5: ='P & D'!N2 -> 0 | M5: ='P & D'!O2 -> 0 | N5: ='P & D'!P2 -> 69 | O5: ='P & D'!Q2 -> 0 | Q5: ='P & D'!U2 -> 0 | R5: ='P & D'!V2 -> 0 | S5: ='P & D'!W2 -> 69 | T5: ='P & D'!X2 -> 0 | U5: ='P & D'!Y2 -> 0
B6: A2 | C6: Durability & Reliability | D6: AL | E6: - | F6: - | G6: =SUM(K6+L6+M6+N6) -> 15 | K6: ='D&R'!M2 -> 0 | L6: ='D&R'!N2 -> 0 | M6: ='D&R'!O2 -> 0 | N6: ='D&R'!P2 -> 15 | O6: ='D&R'!Q1 -> 0 | Q6: ='D&R'!U2 -> 0 | R6: ='D&R'!V2 -> 0 | S6: ='D&R'!W2 -> 15 | T6: ='D&R'!X2 -> 0 | U6: ='D&R'!Y2 -> 0
B7: A3 | C7: Thermal Aerodynamics System Engineering | D7: C | E7: C | F7: C | G7: =SUM(K7+L7+M7+N7) -> 7 | K7: ='Thermal Aerodynamics System Eng'!M2 -> 0 | L7: ='Thermal Aerodynamics System Eng'!N2 -> 0 | M7: ='Thermal Aerodynamics System Eng'!O2 -> 0 | N7: ='Thermal Aerodynamics System Eng'!P2 -> 7 | O7: ='Thermal Aerodynamics System Eng'!Q2 -> 0 | Q7: ='Thermal Aerodynamics System Eng'!U2 -> 0 | R7: ='Thermal Aerodynamics System Eng'!V2 -> 0 | S7: ='Thermal Aerodynamics System Eng'!W2 -> 7 | T7: ='Thermal Aerodynamics System Eng'!X2 -> 0 | U7: ='Thermal Aerodynamics System Eng'!Y2 -> 0
B8: A4 | C8: Utility & Usage | D8: C | E8: AL | F8: AL | G8: =SUM(K8+L8+M8+N8) -> 7 | K8: ='Utility & Usage'!M2 -> 0 | L8: ='Utility & Usage'!N2 -> 0 | M8: ='Utility & Usage'!O2 -> 0 | N8: ='Utility & Usage'!P2 -> 7 | O8: ='Utility & Usage'!Q2 -> 0 | Q8: ='Utility & Usage'!U2 -> 0 | R8: ='Utility & Usage'!V2 -> 0 | S8: ='Utility & Usage'!W2 -> 7 | T8: ='Utility & Usage'!X2 -> 0 | U8: ='Utility & Usage'!Y2 -> 0
B9: A5 | C9: Safety and Security | D9: AL | E9: L | F9: L | G9: =SUM(K9+L9+M9+N9) -> 10 | K9: =Safety!M2 -> 0 | L9: =Safety!N2 -> 0 | M9: =Safety!O2 -> 0 | N9: =Safety!P2 -> 10 | O9: =Safety!Q2 -> 0 | Q9: =Safety!U2 -> 0 | R9: =Safety!V2 -> 0 | S9: =Safety!W2 -> 10 | T9: =Safety!X2 -> 0 | U9: =Safety!Y2 -> 0
B10: A6 | C10: Environment Management | D10: C | E10: - | F10: - | G10: =SUM(K10+L10+M10+N10) -> 4 | K10: ='Environment Mgmt'!M2 -> 0 | L10: ='Environment Mgmt'!N2 -> 0 | M10: ='Environment Mgmt'!O2 -> 0 | N10: ='Environment Mgmt'!P2 -> 4 | O10: ='Environment Mgmt'!Q2 -> 0 | Q10: ='Environment Mgmt'!U2 -> 0 | R10: ='Environment Mgmt'!V2 -> 0 | S10: ='Environment Mgmt'!W2 -> 4 | T10: ='Environment Mgmt'!X2 -> 0 | U10: ='Environment Mgmt'!Y2 -> 0
B11: A7 | C11: HMI | D11: C | E11: - | F11: - | G11: =SUM(K11+L11+M11+N11) -> 24 | K11: =HMI!M2 -> 0 | L11: =HMI!N2 -> 0 | M11: =HMI!O2 -> 0 | N11: =HMI!P2 -> 24 | O11: =HMI!Q2 -> 0 | Q11: =HMI!U2 -> 0 | R11: =HMI!V2 -> 0 | S11: =HMI!W2 -> 24 | T11: =HMI!X2 -> 0 | U11: =HMI!Y2 -> 0
G12: =SUM(G5:G11) -> 136
G13: LEGEND : no.of RED / YELLOW / GREEN / Not assessable/ Not assessed | K13: Data for graphs (Not to be presented )

Sheet Revision_History
C1: Aggregate Attribute Target | H1: Template Number: ATD-ORG-PM-T00X Format Number: PA20-F948.1(R0), April 2023 Project document Number:ATD-ORG-PM-X-in-1-00X Date: 05-05-2023 Version: 0.1
A2: Department | C2: Advance Engineering CVBU
A3: Title | C3: Revision History
A4: Sr.No | B4: Modification or Change | C4: Justification | D4: Change Initiator | E4: Reviewer | F4: Approved by | G4: New Version Number | H4: Date of Issue
A5: 1 | B5: Revision 1 | C5: 1.In house motor parameter consider 2. Duplicate data deleted | D5: Pratik Parale | E5: Pankaj Deosarkar | F5: Rajiv Kumar | G5: Revision _1.0 | H5: 45922
A6: 2 | B6: Revision 2 | C6: 1. Optimisation based on product specification | D6: Pratik Parale | E6: Pankaj Deosarkar | F6: Rajiv Kumar | G6: Revision_6.0 | H6: 46041
A7: 3 | B7: Revision 3 | C7: 1. Optimation in Utility & Usage 2. Optimation in D & R | D7: Pratik Parale | E7: Pankaj Deosarkar | F7: Rajiv Kumar | G7: Revision_7.0 | H7: 46146
A8: 4 | B8: Revision 4 | C8: Targets are assigned for each attribute. | D8: Pratik Parale | E8: Pankaj Deosarkar | F8: Rajiv Kumar | G8: Revision_7.1 | H8: 46156
A9: 5 | B9: Revision 5 | C9: 2 Duplicate targets in P & D , Partial parameter achivable at mule testing | D9: Pratik Parale | E9: Pankaj Deosarkar | F9: Rajiv Kumar | G9: Revision_7.2 | H9: 46238
A10: 6
A11: 7

Sheet INFO
F10: Legend - Current Status | H10: Legend - Projected SOP Status
F11: R - Not meeting target, no recovery plan | H11: R - Not expected to meet target
F12: Y – Not meeting target, recovery plan available | H12: Y – Expected to meet target ( with conference plan, recovery plan available)
F13: G – meeting target | H13: G – meeting target if current status is R or A
F14: NA – Not accessed | H14: NA – Not applicable

Sheet P & D
A1: X-in-1 - TML Inhouse Integrated Domain Controller | L1: AR1 | T1: SOP
A2: # | B2: Level1 | C2: Level2 | D2: Level3 | E2: Level4 | F2: Level5 | H2: Metric | I2: # | J2: Target | L2: Total | M2: =SUM(M4:M130) -> 0 | N2: =SUM(N4:N130) -> 0 | O2: =SUM(O4:O130) -> 0 | P2: =SUM(P4:P130) -> 69 | T2: Total | U2: =SUM(U4:U130) -> 0 | V2: =SUM(V4:V130) -> 0 | W2: =SUM(W4:W130) -> 69 | X2: =SUM(X4:X130) -> 0
A3: 1 | B3: Performance & driveability | L3: Master Status | M3: R | N3: Y | O3: G | P3: B | Q3: Remarks | R3: Actual | T3: Master Status | U3: R | V3: Y | W3: G | X3: B | Y3: Remarks
C4: Vehicle Driving | R4: -
D5: MCU Peak Power for 2Min (Peak) | E5: At Rated RPM of 3343 | H5: KW | J5: 280 | L5: B | M5: =COUNTIFS(L5,"R") -> 0 | N5: =COUNTIFS(L5,"Y") -> 0 | O5: =COUNTIFS(L5,"G") -> 0 | P5: =COUNTIFS(L5,"B") -> 1 | T5: G | U5: =COUNTIFS(T5,"R") -> 0 | V5: =COUNTIFS(T5,"Y") -> 0 | W5: =COUNTIFS(T5,"G") -> 1 | X5: =COUNTIFS(T5,"B") -> 0
E6: At Rated Torque of 450Nm | H6: KW | J6: 280 | L6: B | M6: =COUNTIFS(L6,"R") -> 0 | N6: =COUNTIFS(L6,"Y") -> 0 | O6: =COUNTIFS(L6,"G") -> 0 | P6: =COUNTIFS(L6,"B") -> 1 | T6: G | U6: =COUNTIFS(T6,"R") -> 0 | V6: =COUNTIFS(T6,"Y") -> 0 | W6: =COUNTIFS(T6,"G") -> 1 | X6: =COUNTIFS(T6,"B") -> 0
E7: At Max Temp -20°C to 65°C | H7: KW | J7: 250 | L7: B | M7: =COUNTIFS(L7,"R") -> 0 | N7: =COUNTIFS(L7,"Y") -> 0 | O7: =COUNTIFS(L7,"G") -> 0 | P7: =COUNTIFS(L7,"B") -> 1 | T7: G | U7: =COUNTIFS(T7,"R") -> 0 | V7: =COUNTIFS(T7,"Y") -> 0 | W7: =COUNTIFS(T7,"G") -> 1 | X7: =COUNTIFS(T7,"B") -> 0
D8: MCU continuos Power | E8: At Rated RPM of 3343 | H8: KW | J8: 188 | L8: B | M8: =COUNTIFS(L8,"R") -> 0 | N8: =COUNTIFS(L8,"Y") -> 0 | O8: =COUNTIFS(L8,"G") -> 0 | P8: =COUNTIFS(L8,"B") -> 1 | T8: G | U8: =COUNTIFS(T8,"R") -> 0 | V8: =COUNTIFS(T8,"Y") -> 0 | W8: =COUNTIFS(T8,"G") -> 1 | X8: =COUNTIFS(T8,"B") -> 0
E9: At Rated Torque of 450Nm | H9: KW | J9: 188 | L9: B | M9: =COUNTIFS(L9,"R") -> 0 | N9: =COUNTIFS(L9,"Y") -> 0 | O9: =COUNTIFS(L9,"G") -> 0 | P9: =COUNTIFS(L9,"B") -> 1 | T9: G | U9: =COUNTIFS(T9,"R") -> 0 | V9: =COUNTIFS(T9,"Y") -> 0 | W9: =COUNTIFS(T9,"G") -> 1 | X9: =COUNTIFS(T9,"B") -> 0
E10: At Max Temp -20°C to 85°C | H10: KW | J10: 188 | L10: B | M10: =COUNTIFS(L10,"R") -> 0 | N10: =COUNTIFS(L10,"Y") -> 0 | O10: =COUNTIFS(L10,"G") -> 0 | P10: =COUNTIFS(L10,"B") -> 1 | T10: G | U10: =COUNTIFS(T10,"R") -> 0 | V10: =COUNTIFS(T10,"Y") -> 0 | W10: =COUNTIFS(T10,"G") -> 1 | X10: =COUNTIFS(T10,"B") -> 0
D11: MCU Efficiency | E11: At rated load of 140KW | H11: % | J11: >95 | L11: B | M11: =COUNTIFS(L11,"R") -> 0 | N11: =COUNTIFS(L11,"Y") -> 0 | O11: =COUNTIFS(L11,"G") -> 0 | P11: =COUNTIFS(L11,"B") -> 1 | T11: G | U11: =COUNTIFS(T11,"R") -> 0 | V11: =COUNTIFS(T11,"Y") -> 0 | W11: =COUNTIFS(T11,"G") -> 1 | X11: =COUNTIFS(T11,"B") -> 0
E12: At Max load of 250KW | H12: % | J12: >93 | L12: B | M12: =COUNTIFS(L12,"R") -> 0 | N12: =COUNTIFS(L12,"Y") -> 0 | O12: =COUNTIFS(L12,"G") -> 0 | P12: =COUNTIFS(L12,"B") -> 1 | T12: G | U12: =COUNTIFS(T12,"R") -> 0 | V12: =COUNTIFS(T12,"Y") -> 0 | W12: =COUNTIFS(T12,"G") -> 1 | X12: =COUNTIFS(T12,"B") -> 0
D13: MCU Over Current | E13: At adiititional 30% load(cutoff) | H13: A | J13: >500 | L13: B | M13: =COUNTIFS(L13,"R") -> 0 | N13: =COUNTIFS(L13,"Y") -> 0 | O13: =COUNTIFS(L13,"G") -> 0 | P13: =COUNTIFS(L13,"B") -> 1 | T13: G | U13: =COUNTIFS(T13,"R") -> 0 | V13: =COUNTIFS(T13,"Y") -> 0 | W13: =COUNTIFS(T13,"G") -> 1 | X13: =COUNTIFS(T13,"B") -> 0
E14: At adittinonal 10 % (derate) | H14: A | J14: >450 | L14: B | M14: =COUNTIFS(L14,"R") -> 0 | N14: =COUNTIFS(L14,"Y") -> 0 | O14: =COUNTIFS(L14,"G") -> 0 | P14: =COUNTIFS(L14,"B") -> 1 | T14: G | U14: =COUNTIFS(T14,"R") -> 0 | V14: =COUNTIFS(T14,"Y") -> 0 | W14: =COUNTIFS(T14,"G") -> 1 | X14: =COUNTIFS(T14,"B") -> 0
D15: MCU Over Power | E15: At adiititional 30% load(cutoff) | H15: KW | J15: >250 | L15: B | M15: =COUNTIFS(L15,"R") -> 0 | N15: =COUNTIFS(L15,"Y") -> 0 | O15: =COUNTIFS(L15,"G") -> 0 | P15: =COUNTIFS(L15,"B") -> 1 | T15: G | U15: =COUNTIFS(T15,"R") -> 0 | V15: =COUNTIFS(T15,"Y") -> 0 | W15: =COUNTIFS(T15,"G") -> 1 | X15: =COUNTIFS(T15,"B") -> 0
E16: At adittinonal 10 % (derate) | H16: KW | J16: >235 | L16: B | M16: =COUNTIFS(L16,"R") -> 0 | N16: =COUNTIFS(L16,"Y") -> 0 | O16: =COUNTIFS(L16,"G") -> 0 | P16: =COUNTIFS(L16,"B") -> 1 | T16: G | U16: =COUNTIFS(T16,"R") -> 0 | V16: =COUNTIFS(T16,"Y") -> 0 | W16: =COUNTIFS(T16,"G") -> 1 | X16: =COUNTIFS(T16,"B") -> 0
D17: MCU Over Voltage | E17: At Rated Load | H17: V | J17: 1050 | L17: B | M17: =COUNTIFS(L17,"R") -> 0 | N17: =COUNTIFS(L17,"Y") -> 0 | O17: =COUNTIFS(L17,"G") -> 0 | P17: =COUNTIFS(L17,"B") -> 1 | T17: G | U17: =COUNTIFS(T17,"R") -> 0 | V17: =COUNTIFS(T17,"Y") -> 0 | W17: =COUNTIFS(T17,"G") -> 1 | X17: =COUNTIFS(T17,"B") -> 0
D18: MCU Over Temperature | E18: At 110% of max temp( cutoff) | H18: Deg | J18: 85 | L18: B | M18: =COUNTIFS(L18,"R") -> 0 | N18: =COUNTIFS(L18,"Y") -> 0 | O18: =COUNTIFS(L18,"G") -> 0 | P18: =COUNTIFS(L18,"B") -> 1 | T18: G | U18: =COUNTIFS(T18,"R") -> 0 | V18: =COUNTIFS(T18,"Y") -> 0 | W18: =COUNTIFS(T18,"G") -> 1 | X18: =COUNTIFS(T18,"B") -> 0
E19: At 100% max temp (derate) | H19: Deg | J19: 60 | L19: B | M19: =COUNTIFS(L19,"R") -> 0 | N19: =COUNTIFS(L19,"Y") -> 0 | O19: =COUNTIFS(L19,"G") -> 0 | P19: =COUNTIFS(L19,"B") -> 1 | T19: G | U19: =COUNTIFS(T19,"R") -> 0 | V19: =COUNTIFS(T19,"Y") -> 0 | W19: =COUNTIFS(T19,"G") -> 1 | X19: =COUNTIFS(T19,"B") -> 0
C20: Sterring Pump
D21: Aux inverter Output Current | E21: At Rated Load | H21: A | J21: 7 | L21: B | M21: =COUNTIFS(L21,"R") -> 0 | N21: =COUNTIFS(L21,"Y") -> 0 | O21: =COUNTIFS(L21,"G") -> 0 | P21: =COUNTIFS(L21,"B") -> 1 | T21: G | U21: =COUNTIFS(T21,"R") -> 0 | V21: =COUNTIFS(T21,"Y") -> 0 | W21: =COUNTIFS(T21,"G") -> 1 | X21: =COUNTIFS(T21,"B") -> 0
E22: At Max Temp (-20Deg to 65Deg) | H22: A | J22: 7 | L22: B | M22: =COUNTIFS(L22,"R") -> 0 | N22: =COUNTIFS(L22,"Y") -> 0 | O22: =COUNTIFS(L22,"G") -> 0 | P22: =COUNTIFS(L22,"B") -> 1 | T22: G | U22: =COUNTIFS(T22,"R") -> 0 | V22: =COUNTIFS(T22,"Y") -> 0 | W22: =COUNTIFS(T22,"G") -> 1 | X22: =COUNTIFS(T22,"B") -> 0
D23: Aux inverter Output Power continuos | E23: At rated RPM of 1450 | H23: KW | J23: 3.7 | L23: B | M23: =COUNTIFS(L23,"R") -> 0 | N23: =COUNTIFS(L23,"Y") -> 0 | O23: =COUNTIFS(L23,"G") -> 0 | P23: =COUNTIFS(L23,"B") -> 1 | T23: G | U23: =COUNTIFS(T23,"R") -> 0 | V23: =COUNTIFS(T23,"Y") -> 0 | W23: =COUNTIFS(T23,"G") -> 1 | X23: =COUNTIFS(T23,"B") -> 0
E24: At Rated Load 3.7KW | H24: KW | J24: 3.7 | L24: B | M24: =COUNTIFS(L24,"R") -> 0 | N24: =COUNTIFS(L24,"Y") -> 0 | O24: =COUNTIFS(L24,"G") -> 0 | P24: =COUNTIFS(L24,"B") -> 1 | T24: G | U24: =COUNTIFS(T24,"R") -> 0 | V24: =COUNTIFS(T24,"Y") -> 0 | W24: =COUNTIFS(T24,"G") -> 1 | X24: =COUNTIFS(T24,"B") -> 0
D25: Aux inverter Efficiency | E25: At 100% load of 10KW | H25: % | J25: >95 | L25: B | M25: =COUNTIFS(L25,"R") -> 0 | N25: =COUNTIFS(L25,"Y") -> 0 | O25: =COUNTIFS(L25,"G") -> 0 | P25: =COUNTIFS(L25,"B") -> 1 | T25: G | U25: =COUNTIFS(T25,"R") -> 0 | V25: =COUNTIFS(T25,"Y") -> 0 | W25: =COUNTIFS(T25,"G") -> 1 | X25: =COUNTIFS(T25,"B") -> 0
E26: At rated load of 3.7KW | H26: % | J26: >98 | L26: B | M26: =COUNTIFS(L26,"R") -> 0 | N26: =COUNTIFS(L26,"Y") -> 0 | O26: =COUNTIFS(L26,"G") -> 0 | P26: =COUNTIFS(L26,"B") -> 1 | T26: G | U26: =COUNTIFS(T26,"R") -> 0 | V26: =COUNTIFS(T26,"Y") -> 0 | W26: =COUNTIFS(T26,"G") -> 1 | X26: =COUNTIFS(T26,"B") -> 0
D27: Aux inverter Phase Current A | E27: At Rated Load 3.7KW | H27: A | J27: 7 | L27: B | M27: =COUNTIFS(L27,"R") -> 0 | N27: =COUNTIFS(L27,"Y") -> 0 | O27: =COUNTIFS(L27,"G") -> 0 | P27: =COUNTIFS(L27,"B") -> 1 | T27: G | U27: =COUNTIFS(T27,"R") -> 0 | V27: =COUNTIFS(T27,"Y") -> 0 | W27: =COUNTIFS(T27,"G") -> 1 | X27: =COUNTIFS(T27,"B") -> 0
D28: Aux inverter Phase Current B | E28: At Rated Load 3.7KW | H28: A | J28: 7 | L28: B | M28: =COUNTIFS(L28,"R") -> 0 | N28: =COUNTIFS(L28,"Y") -> 0 | O28: =COUNTIFS(L28,"G") -> 0 | P28: =COUNTIFS(L28,"B") -> 1 | T28: G | U28: =COUNTIFS(T28,"R") -> 0 | V28: =COUNTIFS(T28,"Y") -> 0 | W28: =COUNTIFS(T28,"G") -> 1 | X28: =COUNTIFS(T28,"B") -> 0
D29: Aux inverter Phase Current C | E29: At Rated Load 3.7KW | H29: A | J29: 7 | L29: B | M29: =COUNTIFS(L29,"R") -> 0 | N29: =COUNTIFS(L29,"Y") -> 0 | O29: =COUNTIFS(L29,"G") -> 0 | P29: =COUNTIFS(L29,"B") -> 1 | T29: G | U29: =COUNTIFS(T29,"R") -> 0 | V29: =COUNTIFS(T29,"Y") -> 0 | W29: =COUNTIFS(T29,"G") -> 1 | X29: =COUNTIFS(T29,"B") -> 0
D30: Aux inverter Operating Temperature | E30: At Rated Load 3.7KW | H30: Deg | J30: 85 | L30: B | M30: =COUNTIFS(L30,"R") -> 0 | N30: =COUNTIFS(L30,"Y") -> 0 | O30: =COUNTIFS(L30,"G") -> 0 | P30: =COUNTIFS(L30,"B") -> 1 | T30: G | U30: =COUNTIFS(T30,"R") -> 0 | V30: =COUNTIFS(T30,"Y") -> 0 | W30: =COUNTIFS(T30,"G") -> 1 | X30: =COUNTIFS(T30,"B") -> 0
E31: At rated torque 15Nm | H31: Deg | J31: 65 | L31: B | M31: =COUNTIFS(L31,"R") -> 0 | N31: =COUNTIFS(L31,"Y") -> 0 | O31: =COUNTIFS(L31,"G") -> 0 | P31: =COUNTIFS(L31,"B") -> 1 | T31: G | U31: =COUNTIFS(T31,"R") -> 0 | V31: =COUNTIFS(T31,"Y") -> 0 | W31: =COUNTIFS(T31,"G") -> 1 | X31: =COUNTIFS(T31,"B") -> 0
D32: Aux inverter Over Current | E32: At 130% load(cutoff) | H32: A | J32: >18 | L32: B | M32: =COUNTIFS(L32,"R") -> 0 | N32: =COUNTIFS(L32,"Y") -> 0 | O32: =COUNTIFS(L32,"G") -> 0 | P32: =COUNTIFS(L32,"B") -> 1 | T32: G | U32: =COUNTIFS(T32,"R") -> 0 | V32: =COUNTIFS(T32,"Y") -> 0 | W32: =COUNTIFS(T32,"G") -> 1 | X32: =COUNTIFS(T32,"B") -> 0
E33: At 110 % (derate) | H33: A | J33: >10 | L33: B | M33: =COUNTIFS(L33,"R") -> 0 | N33: =COUNTIFS(L33,"Y") -> 0 | O33: =COUNTIFS(L33,"G") -> 0 | P33: =COUNTIFS(L33,"B") -> 1 | T33: G | U33: =COUNTIFS(T33,"R") -> 0 | V33: =COUNTIFS(T33,"Y") -> 0 | W33: =COUNTIFS(T33,"G") -> 1 | X33: =COUNTIFS(T33,"B") -> 0
D34: Aux inverter Over Power | E34: At 130% load(Cutoff) | H34: KW | J34: >10 | L34: B | M34: =COUNTIFS(L34,"R") -> 0 | N34: =COUNTIFS(L34,"Y") -> 0 | O34: =COUNTIFS(L34,"G") -> 0 | P34: =COUNTIFS(L34,"B") -> 1 | T34: G | U34: =COUNTIFS(T34,"R") -> 0 | V34: =COUNTIFS(T34,"Y") -> 0 | W34: =COUNTIFS(T34,"G") -> 1 | X34: =COUNTIFS(T34,"B") -> 0
E35: At 110 % (derate) | H35: KW | J35: >5 | L35: B | M35: =COUNTIFS(L35,"R") -> 0 | N35: =COUNTIFS(L35,"Y") -> 0 | O35: =COUNTIFS(L35,"G") -> 0 | P35: =COUNTIFS(L35,"B") -> 1 | T35: G | U35: =COUNTIFS(T35,"R") -> 0 | V35: =COUNTIFS(T35,"Y") -> 0 | W35: =COUNTIFS(T35,"G") -> 1 | X35: =COUNTIFS(T35,"B") -> 0
D36: Aux inverter Over Voltage | E36: At Rated Load 3.7KW | H36: V | J36: >1050 | L36: B | M36: =COUNTIFS(L36,"R") -> 0 | N36: =COUNTIFS(L36,"Y") -> 0 | O36: =COUNTIFS(L36,"G") -> 0 | P36: =COUNTIFS(L36,"B") -> 1 | T36: G | U36: =COUNTIFS(T36,"R") -> 0 | V36: =COUNTIFS(T36,"Y") -> 0 | W36: =COUNTIFS(T36,"G") -> 1 | X36: =COUNTIFS(T36,"B") -> 0
D37: Aux inverter Over Temperature | E37: At 110% of max temp( cutoff) | H37: Deg | J37: >85 | L37: B | M37: =COUNTIFS(L37,"R") -> 0 | N37: =COUNTIFS(L37,"Y") -> 0 | O37: =COUNTIFS(L37,"G") -> 0 | P37: =COUNTIFS(L37,"B") -> 1 | T37: G | U37: =COUNTIFS(T37,"R") -> 0 | V37: =COUNTIFS(T37,"Y") -> 0 | W37: =COUNTIFS(T37,"G") -> 1 | X37: =COUNTIFS(T37,"B") -> 0
E38: At 100% max temp (derate) | H38: Deg | J38: >65 | L38: B | M38: =COUNTIFS(L38,"R") -> 0 | N38: =COUNTIFS(L38,"Y") -> 0 | O38: =COUNTIFS(L38,"G") -> 0 | P38: =COUNTIFS(L38,"B") -> 1 | T38: G | U38: =COUNTIFS(T38,"R") -> 0 | V38: =COUNTIFS(T38,"Y") -> 0 | W38: =COUNTIFS(T38,"G") -> 1 | X38: =COUNTIFS(T38,"B") -> 0
C39: Braking system | D39: Aux inverter Output Current | E39: At Rated Load 3.7KW | H39: A | J39: 7 | L39: B | M39: =COUNTIFS(L39,"R") -> 0 | N39: =COUNTIFS(L39,"Y") -> 0 | O39: =COUNTIFS(L39,"G") -> 0 | P39: =COUNTIFS(L39,"B") -> 1 | T39: G | U39: =COUNTIFS(T39,"R") -> 0 | V39: =COUNTIFS(T39,"Y") -> 0 | W39: =COUNTIFS(T39,"G") -> 1 | X39: =COUNTIFS(T39,"B") -> 0
E40: At Rated Torque of 15Nm | H40: A | J40: 7 | L40: B | M40: =COUNTIFS(L40,"R") -> 0 | N40: =COUNTIFS(L40,"Y") -> 0 | O40: =COUNTIFS(L40,"G") -> 0 | P40: =COUNTIFS(L40,"B") -> 1 | T40: G | U40: =COUNTIFS(T40,"R") -> 0 | V40: =COUNTIFS(T40,"Y") -> 0 | W40: =COUNTIFS(T40,"G") -> 1 | X40: =COUNTIFS(T40,"B") -> 0
...

Sheet D&R
A1: X-in-1 - TML Inhouse Integrated Domain Controller | L1: AR1 | T1: SOP
A2: # | B2: Level1 | C2: Level2 | D2: Level3 | E2: Level4 | F2: Level5 | H2: Metric | I2: # | J2: Target | L2: Total | M2: =SUM(M4:M176) -> 0 | N2: =SUM(N4:N176) -> 0 | O2: =SUM(O4:O176) -> 0 | P2: =SUM(P4:P176) -> 15 | T2: Total | U2: =SUM(U4:U176) -> 0 | V2: =SUM(V4:V176) -> 0 | W2: =SUM(W4:W176) -> 15 | X2: =SUM(X4:X176) -> 0
A3: 2 | B3: Vehicle Specification | L3: Master Status | M3: R | N3: Y | O3: G | P3: B | Q3: Remarks | R3: Actual | T3: Master Status | U3: R | V3: Y | W3: G | X3: B | Y3: Remarks
C4: MCU Max Torque | D4: At rated load of 188KW | H4: Nm | J4: 450 | L4: B | M4: =COUNTIFS(L4,"R") -> 0 | N4: =COUNTIFS(L4,"Y") -> 0 | O4: =COUNTIFS(L4,"G") -> 0 | P4: =COUNTIFS(L4,"B") -> 1 | R4: - | T4: G | U4: =COUNTIFS(T4,"R") -> 0 | V4: =COUNTIFS(T4,"Y") -> 0 | W4: =COUNTIFS(T4,"G") -> 1 | X4: =COUNTIFS(T4,"B") -> 0
D5: At Max load of 288KW | H5: Nm | J5: 450 | L5: B | M5: =COUNTIFS(L5,"R") -> 0 | N5: =COUNTIFS(L5,"Y") -> 0 | O5: =COUNTIFS(L5,"G") -> 0 | P5: =COUNTIFS(L5,"B") -> 1 | T5: G | U5: =COUNTIFS(T5,"R") -> 0 | V5: =COUNTIFS(T5,"Y") -> 0 | W5: =COUNTIFS(T5,"G") -> 1 | X5: =COUNTIFS(T5,"B") -> 0
C6: MCU Temperature | D6: At rated load of 188KW | H6: Deg | J6: 85 | L6: B | M6: =COUNTIFS(L6,"R") -> 0 | N6: =COUNTIFS(L6,"Y") -> 0 | O6: =COUNTIFS(L6,"G") -> 0 | P6: =COUNTIFS(L6,"B") -> 1 | T6: G | U6: =COUNTIFS(T6,"R") -> 0 | V6: =COUNTIFS(T6,"Y") -> 0 | W6: =COUNTIFS(T6,"G") -> 1 | X6: =COUNTIFS(T6,"B") -> 0
D7: At Rated torque of 450Nm | H7: Deg | J7: 85 | L7: B | M7: =COUNTIFS(L7,"R") -> 0 | N7: =COUNTIFS(L7,"Y") -> 0 | O7: =COUNTIFS(L7,"G") -> 0 | P7: =COUNTIFS(L7,"B") -> 1 | T7: G | U7: =COUNTIFS(T7,"R") -> 0 | V7: =COUNTIFS(T7,"Y") -> 0 | W7: =COUNTIFS(T7,"G") -> 1 | X7: =COUNTIFS(T7,"B") -> 0
C8: Aux inverter Max Torque | D8: At continuous Load (3.7KW) | H8: Nm | J8: 15 | L8: B | M8: =COUNTIFS(L8,"R") -> 0 | N8: =COUNTIFS(L8,"Y") -> 0 | O8: =COUNTIFS(L8,"G") -> 0 | P8: =COUNTIFS(L8,"B") -> 1 | T8: G | U8: =COUNTIFS(T8,"R") -> 0 | V8: =COUNTIFS(T8,"Y") -> 0 | W8: =COUNTIFS(T8,"G") -> 1 | X8: =COUNTIFS(T8,"B") -> 0
D9: At Max RPM (1450 )will run for less than 2min | H9: Nm | J9: 15 | L9: B | M9: =COUNTIFS(L9,"R") -> 0 | N9: =COUNTIFS(L9,"Y") -> 0 | O9: =COUNTIFS(L9,"G") -> 0 | P9: =COUNTIFS(L9,"B") -> 1 | T9: G | U9: =COUNTIFS(T9,"R") -> 0 | V9: =COUNTIFS(T9,"Y") -> 0 | W9: =COUNTIFS(T9,"G") -> 1 | X9: =COUNTIFS(T9,"B") -> 0
C10: DC-DC Output Current | D10: At rated load (6KW) | H10: A | J10: 250 | L10: B | M10: =COUNTIFS(L10,"R") -> 0 | N10: =COUNTIFS(L10,"Y") -> 0 | O10: =COUNTIFS(L10,"G") -> 0 | P10: =COUNTIFS(L10,"B") -> 1 | Q10: We can test upto 10% of overall load | T10: G | U10: =COUNTIFS(T10,"R") -> 0 | V10: =COUNTIFS(T10,"Y") -> 0 | W10: =COUNTIFS(T10,"G") -> 1 | X10: =COUNTIFS(T10,"B") -> 0
C11: DC-DC Output Voltage | D11: At rated load (6KW) will run for 4 min | H11: V | J11: 24 | L11: B | M11: =COUNTIFS(L11,"R") -> 0 | N11: =COUNTIFS(L11,"Y") -> 0 | O11: =COUNTIFS(L11,"G") -> 0 | P11: =COUNTIFS(L11,"B") -> 1 | Q11: We can test upto 10% of overall load | T11: G | U11: =COUNTIFS(T11,"R") -> 0 | V11: =COUNTIFS(T11,"Y") -> 0 | W11: =COUNTIFS(T11,"G") -> 1 | X11: =COUNTIFS(T11,"B") -> 0
C12: DC-DC Input Voltage | D12: At rated load (6KW) will run for 4 min | H12: V | J12: > 600v and < 1000V | L12: B | M12: =COUNTIFS(L12,"R") -> 0 | N12: =COUNTIFS(L12,"Y") -> 0 | O12: =COUNTIFS(L12,"G") -> 0 | P12: =COUNTIFS(L12,"B") -> 1 | T12: G | U12: =COUNTIFS(T12,"R") -> 0 | V12: =COUNTIFS(T12,"Y") -> 0 | W12: =COUNTIFS(T12,"G") -> 1 | X12: =COUNTIFS(T12,"B") -> 0
C13: DC-DC Output Power | D13: At Max Output Current (250A) will run for 4 min | H13: KW | J13: 6kW | L13: B | M13: =COUNTIFS(L13,"R") -> 0 | N13: =COUNTIFS(L13,"Y") -> 0 | O13: =COUNTIFS(L13,"G") -> 0 | P13: =COUNTIFS(L13,"B") -> 1 | Q13: We can test upto 10% of overall load | T13: G | U13: =COUNTIFS(T13,"R") -> 0 | V13: =COUNTIFS(T13,"Y") -> 0 | W13: =COUNTIFS(T13,"G") -> 1 | X13: =COUNTIFS(T13,"B") -> 0
B14: Highway Durability | C14: Mix Route durability | D14: X in 1 | H14: km | J14: 30000 | L14: B | M14: =COUNTIFS(L14,"R") -> 0 | N14: =COUNTIFS(L14,"Y") -> 0 | O14: =COUNTIFS(L14,"G") -> 0 | P14: =COUNTIFS(L14,"B") -> 1 | T14: G | U14: =COUNTIFS(T14,"R") -> 0 | V14: =COUNTIFS(T14,"Y") -> 0 | W14: =COUNTIFS(T14,"G") -> 1 | X14: =COUNTIFS(T14,"B") -> 0
C15: City durability | D15: X in 1 | H15: km | J15: 30000 | L15: B | M15: =COUNTIFS(L15,"R") -> 0 | N15: =COUNTIFS(L15,"Y") -> 0 | O15: =COUNTIFS(L15,"G") -> 0 | P15: =COUNTIFS(L15,"B") -> 1 | T15: G | U15: =COUNTIFS(T15,"R") -> 0 | V15: =COUNTIFS(T15,"Y") -> 0 | W15: =COUNTIFS(T15,"G") -> 1 | X15: =COUNTIFS(T15,"B") -> 0
C16: Accelerated durability cycles | D16: X in 1 | H16: km | J16: 30000 | L16: B | M16: =COUNTIFS(L16,"R") -> 0 | N16: =COUNTIFS(L16,"Y") -> 0 | O16: =COUNTIFS(L16,"G") -> 0 | P16: =COUNTIFS(L16,"B") -> 1 | T16: G | U16: =COUNTIFS(T16,"R") -> 0 | V16: =COUNTIFS(T16,"Y") -> 0 | W16: =COUNTIFS(T16,"G") -> 1 | X16: =COUNTIFS(T16,"B") -> 0
B17: Aggregate Coverage Life on structural durability & highway Endurance Vehicle | C17: Powertrain | D17: Traction Motor | H17: km | J17: 30000 | L17: B | M17: =COUNTIFS(L17,"R") -> 0 | N17: =COUNTIFS(L17,"Y") -> 0 | O17: =COUNTIFS(L17,"G") -> 0 | P17: =COUNTIFS(L17,"B") -> 1 | T17: G | U17: =COUNTIFS(T17,"R") -> 0 | V17: =COUNTIFS(T17,"Y") -> 0 | W17: =COUNTIFS(T17,"G") -> 1 | X17: =COUNTIFS(T17,"B") -> 0
C18: High Voltage System | D18: X in 1 | H18: km | J18: 30000 | L18: B | M18: =COUNTIFS(L18,"R") -> 0 | N18: =COUNTIFS(L18,"Y") -> 0 | O18: =COUNTIFS(L18,"G") -> 0 | P18: =COUNTIFS(L18,"B") -> 1 | T18: G | U18: =COUNTIFS(T18,"R") -> 0 | V18: =COUNTIFS(T18,"Y") -> 0 | W18: =COUNTIFS(T18,"G") -> 1 | X18: =COUNTIFS(T18,"B") -> 0

Sheet Thermal Aerodynamics System Eng
A1: X-in-1 - TML Inhouse Integrated Domain Controller | L1: AKO | T1: SOP
A2: # | B2: Level1 | C2: Level2 | D2: Level3 | E2: Level4 | F2: Level5 | H2: Metric | I2: # | J2: Target | L2: Total | M2: =SUM(M4:M161) -> 0 | N2: =SUM(N4:N161) -> 0 | O2: =SUM(O4:O161) -> 0 | P2: =SUM(P4:P161) -> 7 | T2: Total | U2: =SUM(U4:U161) -> 0 | V2: =SUM(V4:V161) -> 0 | W2: =SUM(W4:W161) -> 7 | X2: =SUM(X4:X161) -> 0
A3: 3 | B3: Thermal Aerodynamics System Engineering | L3: Master Status | M3: R | N3: Y | O3: G | P3: B | Q3: Remarks | R3: Actual | T3: Master Status | U3: R | V3: Y | W3: G | X3: B | Y3: Remarks
C4: EV specific thermal strategies | D4: Temperature Cutoff limit | H4: °C | J4: ± 1 | L4: B | M4: =COUNTIFS(L4,"R") -> 0 | N4: =COUNTIFS(L4,"Y") -> 0 | O4: =COUNTIFS(L4,"G") -> 0 | P4: =COUNTIFS(L4,"B") -> 1 | T4: G | U4: =COUNTIFS(T4,"R") -> 0 | V4: =COUNTIFS(T4,"Y") -> 0 | W4: =COUNTIFS(T4,"G") -> 1 | X4: =COUNTIFS(T4,"B") -> 0
C5: DC-DC operating temperature limit | D5: Power board | E5: As per TASE Trial min Temperature | H5: °C | J5: ± 1 | L5: B | M5: =COUNTIFS(L5,"R") -> 0 | N5: =COUNTIFS(L5,"Y") -> 0 | O5: =COUNTIFS(L5,"G") -> 0 | P5: =COUNTIFS(L5,"B") -> 1 | T5: G | U5: =COUNTIFS(T5,"R") -> 0 | V5: =COUNTIFS(T5,"Y") -> 0 | W5: =COUNTIFS(T5,"G") -> 1 | X5: =COUNTIFS(T5,"B") -> 0
E6: As per TASE Trial max Temperature | H6: °C | J6: ± 1 | L6: B | M6: =COUNTIFS(L6,"R") -> 0 | N6: =COUNTIFS(L6,"Y") -> 0 | O6: =COUNTIFS(L6,"G") -> 0 | P6: =COUNTIFS(L6,"B") -> 1 | T6: G | U6: =COUNTIFS(T6,"R") -> 0 | V6: =COUNTIFS(T6,"Y") -> 0 | W6: =COUNTIFS(T6,"G") -> 1 | X6: =COUNTIFS(T6,"B") -> 0
C7: Aux inverter operating temperature limit | D7: Power module | E7: As per TASE Trial min Temperature | H7: °C | J7: ± 1 | L7: B | M7: =COUNTIFS(L7,"R") -> 0 | N7: =COUNTIFS(L7,"Y") -> 0 | O7: =COUNTIFS(L7,"G") -> 0 | P7: =COUNTIFS(L7,"B") -> 1 | T7: G | U7: =COUNTIFS(T7,"R") -> 0 | V7: =COUNTIFS(T7,"Y") -> 0 | W7: =COUNTIFS(T7,"G") -> 1 | X7: =COUNTIFS(T7,"B") -> 0
E8: As per TASE Trial max Temperature | H8: °C | J8: ± 1 | L8: B | M8: =COUNTIFS(L8,"R") -> 0 | N8: =COUNTIFS(L8,"Y") -> 0 | O8: =COUNTIFS(L8,"G") -> 0 | P8: =COUNTIFS(L8,"B") -> 1 | T8: G | U8: =COUNTIFS(T8,"R") -> 0 | V8: =COUNTIFS(T8,"Y") -> 0 | W8: =COUNTIFS(T8,"G") -> 1 | X8: =COUNTIFS(T8,"B") -> 0
C9: MCU temperature limit | D9: Power module | E9: As per TASE Trial min Temperature | H9: °C | J9: ± 1 | L9: B | M9: =COUNTIFS(L9,"R") -> 0 | N9: =COUNTIFS(L9,"Y") -> 0 | O9: =COUNTIFS(L9,"G") -> 0 | P9: =COUNTIFS(L9,"B") -> 1 | T9: G | U9: =COUNTIFS(T9,"R") -> 0 | V9: =COUNTIFS(T9,"Y") -> 0 | W9: =COUNTIFS(T9,"G") -> 1 | X9: =COUNTIFS(T9,"B") -> 0
E10: As per TASE Trial max Temperature | H10: °C | J10: ± 1 | L10: B | M10: =COUNTIFS(L10,"R") -> 0 | N10: =COUNTIFS(L10,"Y") -> 0 | O10: =COUNTIFS(L10,"G") -> 0 | P10: =COUNTIFS(L10,"B") -> 1 | T10: G | U10: =COUNTIFS(T10,"R") -> 0 | V10: =COUNTIFS(T10,"Y") -> 0 | W10: =COUNTIFS(T10,"G") -> 1 | X10: =COUNTIFS(T10,"B") -> 0

Sheet Utility & Usage
A1: X-in-1 - TML Inhouse Integrated Domain Controller | L1: AKO | T1: SOP
A2: # | B2: Level1 | C2: Level2 | D2: Level3 | E2: Level4 | F2: Level5 | H2: Metric | I2: # | J2: Target | L2: Total | M2: =SUM(M4:M181) -> 0 | N2: =SUM(N4:N181) -> 0 | O2: =SUM(O4:O181) -> 0 | P2: =SUM(P4:P181) -> 7 | T2: Total | U2: =SUM(U4:U181) -> 0 | V2: =SUM(V4:V181) -> 0 | W2: =SUM(W4:W181) -> 7 | X2: =SUM(X4:X181) -> 0
A3: 4 | B3: Utility & Usage | L3: Master Status | M3: R | N3: Y | O3: G | P3: B | Q3: Remarks | R3: Actual | T3: Master Status | U3: R | V3: Y | W3: G | X3: B | Y3: Remarks
C4: Charging Fast charging profile | D4: Fast Charging Time | E4: At Max Output Current(TBD) | H4: A | J4: 414 | L4: B | M4: =COUNTIFS(L4,"R") -> 0 | N4: =COUNTIFS(L4,"Y") -> 0 | O4: =COUNTIFS(L4,"G") -> 0 | P4: =COUNTIFS(L4,"B") -> 1 | R4: - | T4: G | U4: =COUNTIFS(T4,"R") -> 0 | V4: =COUNTIFS(T4,"Y") -> 0 | W4: =COUNTIFS(T4,"G") -> 1 | X4: =COUNTIFS(T4,"B") -> 0
E5: At rated Output Current (TBD) | H5: A | J5: 384 | L5: B | M5: =COUNTIFS(L5,"R") -> 0 | N5: =COUNTIFS(L5,"Y") -> 0 | O5: =COUNTIFS(L5,"G") -> 0 | P5: =COUNTIFS(L5,"B") -> 1 | R5: - | T5: G | U5: =COUNTIFS(T5,"R") -> 0 | V5: =COUNTIFS(T5,"Y") -> 0 | W5: =COUNTIFS(T5,"G") -> 1 | X5: =COUNTIFS(T5,"B") -> 0
E6: From 10 % to 90% SOC | H6: Min | J6: 120 | L6: B | M6: =COUNTIFS(L6,"R") -> 0 | N6: =COUNTIFS(L6,"Y") -> 0 | O6: =COUNTIFS(L6,"G") -> 0 | P6: =COUNTIFS(L6,"B") -> 1 | R6: - | T6: G | U6: =COUNTIFS(T6,"R") -> 0 | V6: =COUNTIFS(T6,"Y") -> 0 | W6: =COUNTIFS(T6,"G") -> 1 | X6: =COUNTIFS(T6,"B") -> 0
D7: Over Charging Current | E7: From 90% SOC | H7: A | J7: As per CCL limit | L7: B | M7: =COUNTIFS(L7,"R") -> 0 | N7: =COUNTIFS(L7,"Y") -> 0 | O7: =COUNTIFS(L7,"G") -> 0 | P7: =COUNTIFS(L7,"B") -> 1 | R7: - | T7: G | U7: =COUNTIFS(T7,"R") -> 0 | V7: =COUNTIFS(T7,"Y") -> 0 | W7: =COUNTIFS(T7,"G") -> 1 | X7: =COUNTIFS(T7,"B") -> 0
E8: From 95% SOC | H8: A | J8: 476 | L8: B | M8: =COUNTIFS(L8,"R") -> 0 | N8: =COUNTIFS(L8,"Y") -> 0 | O8: =COUNTIFS(L8,"G") -> 0 | P8: =COUNTIFS(L8,"B") -> 1 | R8: - | T8: G | U8: =COUNTIFS(T8,"R") -> 0 | V8: =COUNTIFS(T8,"Y") -> 0 | W8: =COUNTIFS(T8,"G") -> 1 | X8: =COUNTIFS(T8,"B") -> 0
D9: Over Voltage | E9: From 90% SOC | H9: V | J9: 725 | L9: B | M9: =COUNTIFS(L9,"R") -> 0 | N9: =COUNTIFS(L9,"Y") -> 0 | O9: =COUNTIFS(L9,"G") -> 0 | P9: =COUNTIFS(L9,"B") -> 1 | R9: - | T9: G | U9: =COUNTIFS(T9,"R") -> 0 | V9: =COUNTIFS(T9,"Y") -> 0 | W9: =COUNTIFS(T9,"G") -> 1 | X9: =COUNTIFS(T9,"B") -> 0
E10: From 95% SOC | H10: V | J10: 744.6 | L10: B | M10: =COUNTIFS(L10,"R") -> 0 | N10: =COUNTIFS(L10,"Y") -> 0 | O10: =COUNTIFS(L10,"G") -> 0 | P10: =COUNTIFS(L10,"B") -> 1 | R10: - | T10: G | U10: =COUNTIFS(T10,"R") -> 0 | V10: =COUNTIFS(T10,"Y") -> 0 | W10: =COUNTIFS(T10,"G") -> 1 | X10: =COUNTIFS(T10,"B") -> 0

Sheet Safety
A1: X-in-1 - TML Inhouse Integrated Domain Controller | L1: AKO | T1: SOP
A2: # | B2: Level1 | C2: Level2 | D2: Level3 | E2: Level4 | F2: Level5 | H2: Metric | I2: # | J2: Target | L2: Total | M2: =SUM(M4:M192) -> 0 | N2: =SUM(N4:N192) -> 0 | O2: =SUM(O4:O192) -> 0 | P2: =SUM(P4:P192) -> 10 | T2: Total | U2: =SUM(U4:U192) -> 0 | V2: =SUM(V4:V192) -> 0 | W2: =SUM(W4:W192) -> 10 | X2: =SUM(X4:X192) -> 0
B3: Safety | L3: Master Status | M3: R | N3: Y | O3: G | P3: B | Q3: Remarks | R3: Actual | T3: Master Status | U3: R | V3: Y | W3: G | X3: B | Y3: Remarks
C4: Active Safety | D4: HVIL | E4: X in1 | H4: Digital | J4: 0/1 | L4: B | M4: =COUNTIFS(L4,"R") -> 0 | N4: =COUNTIFS(L4,"Y") -> 0 | O4: =COUNTIFS(L4,"G") -> 0 | P4: =COUNTIFS(L4,"B") -> 1 | R4: - | T4: G | U4: =COUNTIFS(T4,"R") -> 0 | V4: =COUNTIFS(T4,"Y") -> 0 | W4: =COUNTIFS(T4,"G") -> 1 | X4: =COUNTIFS(T4,"B") -> 0
D5: Pre-Charge | E5: MCU precharge in XX | H5: Sec | J5: From Vehicle targets | L5: B | M5: =COUNTIFS(L5,"R") -> 0 | N5: =COUNTIFS(L5,"Y") -> 0 | O5: =COUNTIFS(L5,"G") -> 0 | P5: =COUNTIFS(L5,"B") -> 1 | R5: - | T5: G | U5: =COUNTIFS(T5,"R") -> 0 | V5: =COUNTIFS(T5,"Y") -> 0 | W5: =COUNTIFS(T5,"G") -> 1 | X5: =COUNTIFS(T5,"B") -> 0
E6: DCDC precharge in XX | H6: Sec | J6: From Vehicle targets | L6: B | M6: =COUNTIFS(L6,"R") -> 0 | N6: =COUNTIFS(L6,"Y") -> 0 | O6: =COUNTIFS(L6,"G") -> 0 | P6: =COUNTIFS(L6,"B") -> 1 | R6: - | T6: G | U6: =COUNTIFS(T6,"R") -> 0 | V6: =COUNTIFS(T6,"Y") -> 0 | W6: =COUNTIFS(T6,"G") -> 1 | X6: =COUNTIFS(T6,"B") -> 0
E7: Aux Pre Charge in XX | H7: Sec | J7: From Vehicle targets | L7: B | M7: =COUNTIFS(L7,"R") -> 0 | N7: =COUNTIFS(L7,"Y") -> 0 | O7: =COUNTIFS(L7,"G") -> 0 | P7: =COUNTIFS(L7,"B") -> 1 | R7: - | T7: G | U7: =COUNTIFS(T7,"R") -> 0 | V7: =COUNTIFS(T7,"Y") -> 0 | W7: =COUNTIFS(T7,"G") -> 1 | X7: =COUNTIFS(T7,"B") -> 0
D8: Dis-Charge | E8: MCU Dis charge in XX | H8: Sec | J8: From Vehicle targets | L8: B | M8: =COUNTIFS(L8,"R") -> 0 | N8: =COUNTIFS(L8,"Y") -> 0 | O8: =COUNTIFS(L8,"G") -> 0 | P8: =COUNTIFS(L8,"B") -> 1 | R8: - | T8: G | U8: =COUNTIFS(T8,"R") -> 0 | V8: =COUNTIFS(T8,"Y") -> 0 | W8: =COUNTIFS(T8,"G") -> 1 | X8: =COUNTIFS(T8,"B") -> 0
E9: Aux Dis Charge in XX | H9: Sec | J9: From Vehicle targets | L9: B | M9: =COUNTIFS(L9,"R") -> 0 | N9: =COUNTIFS(L9,"Y") -> 0 | O9: =COUNTIFS(L9,"G") -> 0 | P9: =COUNTIFS(L9,"B") -> 1 | R9: - | T9: G | U9: =COUNTIFS(T9,"R") -> 0 | V9: =COUNTIFS(T9,"Y") -> 0 | W9: =COUNTIFS(T9,"G") -> 1 | X9: =COUNTIFS(T9,"B") -> 0
C10: Functional Safety | D10: X in 1 MCU | H10: ASIL | J10: C/D | L10: B | M10: =COUNTIFS(L10,"R") -> 0 | N10: =COUNTIFS(L10,"Y") -> 0 | O10: =COUNTIFS(L10,"G") -> 0 | P10: =COUNTIFS(L10,"B") -> 1 | Q10: ` | R10: - | T10: G | U10: =COUNTIFS(T10,"R") -> 0 | V10: =COUNTIFS(T10,"Y") -> 0 | W10: =COUNTIFS(T10,"G") -> 1 | X10: =COUNTIFS(T10,"B") -> 0
D11: X in 1 DC-DC | H11: ASIL | J11: B | L11: B | M11: =COUNTIFS(L11,"R") -> 0 | N11: =COUNTIFS(L11,"Y") -> 0 | O11: =COUNTIFS(L11,"G") -> 0 | P11: =COUNTIFS(L11,"B") -> 1 | Q11: ` | R11: - | T11: G | U11: =COUNTIFS(T11,"R") -> 0 | V11: =COUNTIFS(T11,"Y") -> 0 | W11: =COUNTIFS(T11,"G") -> 1 | X11: =COUNTIFS(T11,"B") -> 0
D12: X in 1 AUX | H12: ASIL | J12: C/D | L12: B | M12: =COUNTIFS(L12,"R") -> 0 | N12: =COUNTIFS(L12,"Y") -> 0 | O12: =COUNTIFS(L12,"G") -> 0 | P12: =COUNTIFS(L12,"B") -> 1 | Q12: ` | R12: - | T12: G | U12: =COUNTIFS(T12,"R") -> 0 | V12: =COUNTIFS(T12,"Y") -> 0 | W12: =COUNTIFS(T12,"G") -> 1 | X12: =COUNTIFS(T12,"B") -> 0
D13: X in 1 VCU | H13: ASIL | J13: C/D | L13: B | M13: =COUNTIFS(L13,"R") -> 0 | N13: =COUNTIFS(L13,"Y") -> 0 | O13: =COUNTIFS(L13,"G") -> 0 | P13: =COUNTIFS(L13,"B") -> 1 | Q13: ` | R13: - | T13: G | U13: =COUNTIFS(T13,"R") -> 0 | V13: =COUNTIFS(T13,"Y") -> 0 | W13: =COUNTIFS(T13,"G") -> 1 | X13: =COUNTIFS(T13,"B") -> 0

Sheet Environment Mgmt
A1: X-in-1 - TML Inhouse Integrated Domain Controller | L1: AKO | T1: SOP
A2: # | B2: Level1 | C2: Level2 | D2: Level3 | E2: Level4 | F2: Level5 | H2: Metric | I2: # | J2: Target | L2: Total | M2: =SUM(M4:M171) -> 0 | N2: =SUM(N4:N171) -> 0 | O2: =SUM(O4:O171) -> 0 | P2: =SUM(P4:P171) -> 4 | T2: Total | U2: =SUM(U4:U171) -> 0 | V2: =SUM(V4:V171) -> 0 | W2: =SUM(W4:W171) -> 4 | X2: =SUM(X4:X171) -> 0
A3: 6 | B3: Enviornment Management | L3: Master Status | M3: R | N3: Y | O3: G | P3: B | Q3: Remarks | R3: Actual | T3: Master Status | U3: R | V3: Y | W3: G | X3: B | Y3: Remarks
A4: 6.1 | C4: Regulations for EV Components | D4: AIS 038 for X in 1 | H4: Certification | J4: Pass | L4: B | M4: =COUNTIFS(L4,"R") -> 0 | N4: =COUNTIFS(L4,"Y") -> 0 | O4: =COUNTIFS(L4,"G") -> 0 | P4: =COUNTIFS(L4,"B") -> 1 | R4: - | T4: G | U4: =COUNTIFS(T4,"R") -> 0 | V4: =COUNTIFS(T4,"Y") -> 0 | W4: =COUNTIFS(T4,"G") -> 1 | X4: =COUNTIFS(T4,"B") -> 0
A5: 6.2 | D5: AIS 004 part 3 for X in 1 | H5: Certification | J5: Pass | L5: B | M5: =COUNTIFS(L5,"R") -> 0 | N5: =COUNTIFS(L5,"Y") -> 0 | O5: =COUNTIFS(L5,"G") -> 0 | P5: =COUNTIFS(L5,"B") -> 1 | R5: - | T5: G | U5: =COUNTIFS(T5,"R") -> 0 | V5: =COUNTIFS(T5,"Y") -> 0 | W5: =COUNTIFS(T5,"G") -> 1 | X5: =COUNTIFS(T5,"B") -> 0
D6: Material - Hazardous, Heavy Metals Lead Mercury | H6: Declaration | J6: complinace | L6: B | M6: =COUNTIFS(L6,"R") -> 0 | N6: =COUNTIFS(L6,"Y") -> 0 | O6: =COUNTIFS(L6,"G") -> 0 | P6: =COUNTIFS(L6,"B") -> 1 | T6: G | U6: =COUNTIFS(T6,"R") -> 0 | V6: =COUNTIFS(T6,"Y") -> 0 | W6: =COUNTIFS(T6,"G") -> 1 | X6: =COUNTIFS(T6,"B") -> 0
A7: 6.4 | D7: Elimination of Persistant Organic Pollutants | H7: Declaration | J7: complinace | L7: B | M7: =COUNTIFS(L7,"R") -> 0 | N7: =COUNTIFS(L7,"Y") -> 0 | O7: =COUNTIFS(L7,"G") -> 0 | P7: =COUNTIFS(L7,"B") -> 1 | R7: - | T7: G | U7: =COUNTIFS(T7,"R") -> 0 | V7: =COUNTIFS(T7,"Y") -> 0 | W7: =COUNTIFS(T7,"G") -> 1 | X7: =COUNTIFS(T7,"B") -> 0

Sheet HMI
A1: X-in-1 - TML Inhouse Integrated Domain Controller | L1: AKO | T1: SOP
A2: # | B2: Level1 | C2: Level2 | D2: Level3 | E2: Level4 | F2: Level5 | H2: Metric | I2: # | J2: Target | L2: Total | M2: =SUM(M4:M210) -> 0 | N2: =SUM(N4:N210) -> 0 | O2: =SUM(O4:O210) -> 0 | P2: =SUM(P4:P210) -> 24 | T2: Total | U2: =SUM(U4:U210) -> 0 | V2: =SUM(V4:V210) -> 0 | W2: =SUM(W4:W210) -> 24 | X2: =SUM(X4:X210) -> 0
B3: HMI | L3: Master Status | M3: R | N3: Y | O3: G | P3: B | Q3: Remarks | R3: Actual | T3: Master Status | U3: R | V3: Y | W3: G | X3: B | Y3: Remarks
C4: Charging time | D4: Fast Charging | H4: Hrs | J4: From Vehicle Target | L4: B | M4: =COUNTIFS(L4,"R") -> 0 | N4: =COUNTIFS(L4,"Y") -> 0 | O4: =COUNTIFS(L4,"G") -> 0 | P4: =COUNTIFS(L4,"B") -> 1 | T4: G | U4: =COUNTIFS(T4,"R") -> 0 | V4: =COUNTIFS(T4,"Y") -> 0 | W4: =COUNTIFS(T4,"G") -> 1 | X4: =COUNTIFS(T4,"B") -> 0
C5: EVCU | D5: Distance to empty | H5: KM | J5: From Vehicle Target | L5: B | M5: =COUNTIFS(L5,"R") -> 0 | N5: =COUNTIFS(L5,"Y") -> 0 | O5: =COUNTIFS(L5,"G") -> 0 | P5: =COUNTIFS(L5,"B") -> 1 | T5: G | U5: =COUNTIFS(T5,"R") -> 0 | V5: =COUNTIFS(T5,"Y") -> 0 | W5: =COUNTIFS(T5,"G") -> 1 | X5: =COUNTIFS(T5,"B") -> 0
D6: Time to charge | H6: Hrs | J6: From Vehicle Target | L6: B | M6: =COUNTIFS(L6,"R") -> 0 | N6: =COUNTIFS(L6,"Y") -> 0 | O6: =COUNTIFS(L6,"G") -> 0 | P6: =COUNTIFS(L6,"B") -> 1 | T6: G | U6: =COUNTIFS(T6,"R") -> 0 | V6: =COUNTIFS(T6,"Y") -> 0 | W6: =COUNTIFS(T6,"G") -> 1 | X6: =COUNTIFS(T6,"B") -> 0
D7: Temp indication | E7: Alarm | H7: Indication | J7: Indication on cluster | L7: B | M7: =COUNTIFS(L7,"R") -> 0 | N7: =COUNTIFS(L7,"Y") -> 0 | O7: =COUNTIFS(L7,"G") -> 0 | P7: =COUNTIFS(L7,"B") -> 1 | T7: G | U7: =COUNTIFS(T7,"R") -> 0 | V7: =COUNTIFS(T7,"Y") -> 0 | W7: =COUNTIFS(T7,"G") -> 1 | X7: =COUNTIFS(T7,"B") -> 0
E8: warning | H8: Indication | J8: Indication on cluster | L8: B | M8: =COUNTIFS(L8,"R") -> 0 | N8: =COUNTIFS(L8,"Y") -> 0 | O8: =COUNTIFS(L8,"G") -> 0 | P8: =COUNTIFS(L8,"B") -> 1 | T8: G | U8: =COUNTIFS(T8,"R") -> 0 | V8: =COUNTIFS(T8,"Y") -> 0 | W8: =COUNTIFS(T8,"G") -> 1 | X8: =COUNTIFS(T8,"B") -> 0
D9: Vehicle Speed | E9: Max | H9: RPM | J9: From Motor Target | L9: B | M9: =COUNTIFS(L9,"R") -> 0 | N9: =COUNTIFS(L9,"Y") -> 0 | O9: =COUNTIFS(L9,"G") -> 0 | P9: =COUNTIFS(L9,"B") -> 1 | T9: G | U9: =COUNTIFS(T9,"R") -> 0 | V9: =COUNTIFS(T9,"Y") -> 0 | W9: =COUNTIFS(T9,"G") -> 1 | X9: =COUNTIFS(T9,"B") -> 0
E10: Min | H10: RPM | J10: From Motor Target | L10: B | M10: =COUNTIFS(L10,"R") -> 0 | N10: =COUNTIFS(L10,"Y") -> 0 | O10: =COUNTIFS(L10,"G") -> 0 | P10: =COUNTIFS(L10,"B") -> 1 | T10: G | U10: =COUNTIFS(T10,"R") -> 0 | V10: =COUNTIFS(T10,"Y") -> 0 | W10: =COUNTIFS(T10,"G") -> 1 | X10: =COUNTIFS(T10,"B") -> 0
D11: DNR status | E11: Drive ( ECO) | H11: Mode | J11: D on Cluster | L11: B | M11: =COUNTIFS(L11,"R") -> 0 | N11: =COUNTIFS(L11,"Y") -> 0 | O11: =COUNTIFS(L11,"G") -> 0 | P11: =COUNTIFS(L11,"B") -> 1 | T11: G | U11: =COUNTIFS(T11,"R") -> 0 | V11: =COUNTIFS(T11,"Y") -> 0 | W11: =COUNTIFS(T11,"G") -> 1 | X11: =COUNTIFS(T11,"B") -> 0
E12: Reverse | H12: Mode | J12: R on Cluster | L12: B | M12: =COUNTIFS(L12,"R") -> 0 | N12: =COUNTIFS(L12,"Y") -> 0 | O12: =COUNTIFS(L12,"G") -> 0 | P12: =COUNTIFS(L12,"B") -> 1 | T12: G | U12: =COUNTIFS(T12,"R") -> 0 | V12: =COUNTIFS(T12,"Y") -> 0 | W12: =COUNTIFS(T12,"G") -> 1 | X12: =COUNTIFS(T12,"B") -> 0
E13: Park | H13: Mode | J13: P on cluster | L13: B | M13: =COUNTIFS(L13,"R") -> 0 | N13: =COUNTIFS(L13,"Y") -> 0 | O13: =COUNTIFS(L13,"G") -> 0 | P13: =COUNTIFS(L13,"B") -> 1 | T13: G | U13: =COUNTIFS(T13,"R") -> 0 | V13: =COUNTIFS(T13,"Y") -> 0 | W13: =COUNTIFS(T13,"G") -> 1 | X13: =COUNTIFS(T13,"B") -> 0
E14: Drive(Power ) | H14: Mode | J14: Power on Cluster | L14: B | M14: =COUNTIFS(L14,"R") -> 0 | N14: =COUNTIFS(L14,"Y") -> 0 | O14: =COUNTIFS(L14,"G") -> 0 | P14: =COUNTIFS(L14,"B") -> 1 | T14: G | U14: =COUNTIFS(T14,"R") -> 0 | V14: =COUNTIFS(T14,"Y") -> 0 | W14: =COUNTIFS(T14,"G") -> 1 | X14: =COUNTIFS(T14,"B") -> 0
E15: Neutral | H15: Mode | J15: N on Cluster | L15: B | M15: =COUNTIFS(L15,"R") -> 0 | N15: =COUNTIFS(L15,"Y") -> 0 | O15: =COUNTIFS(L15,"G") -> 0 | P15: =COUNTIFS(L15,"B") -> 1 | T15: G | U15: =COUNTIFS(T15,"R") -> 0 | V15: =COUNTIFS(T15,"Y") -> 0 | W15: =COUNTIFS(T15,"G") -> 1 | X15: =COUNTIFS(T15,"B") -> 0
E16: Limp mode | H16: Mode | J16: L on Cluster | L16: B | M16: =COUNTIFS(L16,"R") -> 0 | N16: =COUNTIFS(L16,"Y") -> 0 | O16: =COUNTIFS(L16,"G") -> 0 | P16: =COUNTIFS(L16,"B") -> 1 | T16: G | U16: =COUNTIFS(T16,"R") -> 0 | V16: =COUNTIFS(T16,"Y") -> 0 | W16: =COUNTIFS(T16,"G") -> 1 | X16: =COUNTIFS(T16,"B") -> 0
D17: Charging | E17: Charging in progress | H17: Status | J17: Indication on cluster | L17: B | M17: =COUNTIFS(L17,"R") -> 0 | N17: =COUNTIFS(L17,"Y") -> 0 | O17: =COUNTIFS(L17,"G") -> 0 | P17: =COUNTIFS(L17,"B") -> 1 | T17: G | U17: =COUNTIFS(T17,"R") -> 0 | V17: =COUNTIFS(T17,"Y") -> 0 | W17: =COUNTIFS(T17,"G") -> 1 | X17: =COUNTIFS(T17,"B") -> 0
E18: Charging fault | H18: Indication | J18: Indication on cluster | L18: B | M18: =COUNTIFS(L18,"R") -> 0 | N18: =COUNTIFS(L18,"Y") -> 0 | O18: =COUNTIFS(L18,"G") -> 0 | P18: =COUNTIFS(L18,"B") -> 1 | T18: G | U18: =COUNTIFS(T18,"R") -> 0 | V18: =COUNTIFS(T18,"Y") -> 0 | W18: =COUNTIFS(T18,"G") -> 1 | X18: =COUNTIFS(T18,"B") -> 0
E19: Charging completion | H19: Status | J19: Indication on cluster | L19: B | M19: =COUNTIFS(L19,"R") -> 0 | N19: =COUNTIFS(L19,"Y") -> 0 | O19: =COUNTIFS(L19,"G") -> 0 | P19: =COUNTIFS(L19,"B") -> 1 | T19: G | U19: =COUNTIFS(T19,"R") -> 0 | V19: =COUNTIFS(T19,"Y") -> 0 | W19: =COUNTIFS(T19,"G") -> 1 | X19: =COUNTIFS(T19,"B") -> 0
D20: SOC | E20: Low SOC | H20: SOC | J20: Indication on cluster | L20: B | M20: =COUNTIFS(L20,"R") -> 0 | N20: =COUNTIFS(L20,"Y") -> 0 | O20: =COUNTIFS(L20,"G") -> 0 | P20: =COUNTIFS(L20,"B") -> 1 | T20: G | U20: =COUNTIFS(T20,"R") -> 0 | V20: =COUNTIFS(T20,"Y") -> 0 | W20: =COUNTIFS(T20,"G") -> 1 | X20: =COUNTIFS(T20,"B") -> 0
E21: SOC warning | H21: Indication | J21: Indication on cluster | L21: B | M21: =COUNTIFS(L21,"R") -> 0 | N21: =COUNTIFS(L21,"Y") -> 0 | O21: =COUNTIFS(L21,"G") -> 0 | P21: =COUNTIFS(L21,"B") -> 1 | T21: G | U21: =COUNTIFS(T21,"R") -> 0 | V21: =COUNTIFS(T21,"Y") -> 0 | W21: =COUNTIFS(T21,"G") -> 1 | X21: =COUNTIFS(T21,"B") -> 0
E22: Full charge | H22: Status | J22: Indication on cluster | L22: B | M22: =COUNTIFS(L22,"R") -> 0 | N22: =COUNTIFS(L22,"Y") -> 0 | O22: =COUNTIFS(L22,"G") -> 0 | P22: =COUNTIFS(L22,"B") -> 1 | T22: G | U22: =COUNTIFS(T22,"R") -> 0 | V22: =COUNTIFS(T22,"Y") -> 0 | W22: =COUNTIFS(T22,"G") -> 1 | X22: =COUNTIFS(T22,"B") -> 0
E23: SOC value | H23: SOC | J23: 0-100% | L23: B | M23: =COUNTIFS(L23,"R") -> 0 | N23: =COUNTIFS(L23,"Y") -> 0 | O23: =COUNTIFS(L23,"G") -> 0 | P23: =COUNTIFS(L23,"B") -> 1 | T23: G | U23: =COUNTIFS(T23,"R") -> 0 | V23: =COUNTIFS(T23,"Y") -> 0 | W23: =COUNTIFS(T23,"G") -> 1 | X23: =COUNTIFS(T23,"B") -> 0
D24: HV battery fault | H24: Indication | J24: Indication on cluster | L24: B | M24: =COUNTIFS(L24,"R") -> 0 | N24: =COUNTIFS(L24,"Y") -> 0 | O24: =COUNTIFS(L24,"G") -> 0 | P24: =COUNTIFS(L24,"B") -> 1 | T24: G | U24: =COUNTIFS(T24,"R") -> 0 | V24: =COUNTIFS(T24,"Y") -> 0 | W24: =COUNTIFS(T24,"G") -> 1 | X24: =COUNTIFS(T24,"B") -> 0
D25: Electric Hazard | H25: Indication | J25: Indication on cluster | L25: B | M25: =COUNTIFS(L25,"R") -> 0 | N25: =COUNTIFS(L25,"Y") -> 0 | O25: =COUNTIFS(L25,"G") -> 0 | P25: =COUNTIFS(L25,"B") -> 1 | T25: G | U25: =COUNTIFS(T25,"R") -> 0 | V25: =COUNTIFS(T25,"Y") -> 0 | W25: =COUNTIFS(T25,"G") -> 1 | X25: =COUNTIFS(T25,"B") -> 0
D26: HVIL | E26: Heathy | H26: Status | J26: Indication on cluster | L26: B | M26: =COUNTIFS(L26,"R") -> 0 | N26: =COUNTIFS(L26,"Y") -> 0 | O26: =COUNTIFS(L26,"G") -> 0 | P26: =COUNTIFS(L26,"B") -> 1 | T26: G | U26: =COUNTIFS(T26,"R") -> 0 | V26: =COUNTIFS(T26,"Y") -> 0 | W26: =COUNTIFS(T26,"G") -> 1 | X26: =COUNTIFS(T26,"B") -> 0
E27: Fault | H27: Status | J27: Indication on cluster | L27: B | M27: =COUNTIFS(L27,"R") -> 0 | N27: =COUNTIFS(L27,"Y") -> 0 | O27: =COUNTIFS(L27,"G") -> 0 | P27: =COUNTIFS(L27,"B") -> 1 | T27: G | U27: =COUNTIFS(T27,"R") -> 0 | V27: =COUNTIFS(T27,"Y") -> 0 | W27: =COUNTIFS(T27,"G") -> 1 | X27: =COUNTIFS(T27,"B") -> 0
